<?xml version="1.0"?>
<robot name="idk" xmlns:xacro="http://ros.org/wiki/xacro">
  <link name="base_link">
    <visual>
      <geometry>
        <box size="0.4 0.28 0.05"/>
      </geometry>
      <material name="blue">
        <color rgba="0 0 .8 1"/>
      </material>
    </visual>
  </link>

  <link name="right_leg">
    <visual>
      <geometry>
        <box size="0.05 .3 .3"/>
      </geometry>
      <origin rpy="0 0 0" xyz="0 0 -0.3"/>
      <material name="white">
        <color rgba="1 1 1 1"/>
      </material>
    </visual>
  </link>

  <joint name="base_to_right_leg" type="fixed">
    <parent link="base_link"/>
    <child link="right_leg"/>
    <origin xyz="0.20 0 .35"/>
  </joint>

  <link name="right_base">
    <visual>
      <geometry>
        <box size=".1 0.4 .1"/>
      </geometry>
      <material name="white"/>
    </visual>
  </link>

  <joint name="right_base_joint" type="fixed">
    <parent link="right_leg"/>
    <child link="right_base"/>
    <origin xyz="0 0 -0.5"/>
  </joint>

  <link name="right_front_wheel">
    <visual>
      <geometry>
        <cylinder length=".1" radius="0.035"/>
      </geometry>
      <material name="black">
        <color rgba="0 0 0 1"/>
      </material>
    </visual>
  </link>

  <joint name="right_front_wheel_joint" type="continuous">
    <axis xyz="0 0 1"/>
    <parent link="right_base"/>
    <child link="right_front_wheel"/>
    <origin rpy="0 1.57075 0" xyz="0 0.133333333333 -0.085"/>
    <limit effort="100" velocity="100"/>
    <dynamics damping="0.0" friction="0.0"/>
  </joint>

  <link name="right_back_wheel">
    <visual>
      <geometry>
        <cylinder length=".1" radius="0.035"/>
      </geometry>
      <material name="black"/>
    </visual>
  </link>

  <joint name="right_back_wheel_joint" type="continuous">
    <axis xyz="0 0 1"/>
    <parent link="right_base"/>
    <child link="right_back_wheel"/>
    <origin rpy="0 1.57075 0" xyz="0 -0.133333333333 -0.085"/>
    <limit effort="100" velocity="100"/>
    <dynamics damping="0.0" friction="0.0"/>
  </joint>

  <link name="left_leg">
    <visual>
      <geometry>
        <box size="0.05 .3 .3"/>
      </geometry>
      <origin rpy="0 0 0" xyz="0 0 -0.3"/>
      <material name="white"/>
    </visual>
  </link>

  <joint name="base_to_left_leg" type="fixed">
    <parent link="base_link"/>
    <child link="left_leg"/>
    <origin xyz="-0.20 0 .35"/>
  </joint>

  <link name="left_base">
    <visual>
      <geometry>
        <box size=".1 0.4 .1"/>
      </geometry>
      <material name="white"/>
    </visual>
  </link>

  <joint name="left_base_joint" type="fixed">
    <parent link="left_leg"/>
    <child link="left_base"/>
    <origin xyz="0 0 -0.5"/>
  </joint>

  <link name="left_front_wheel">
    <visual>
      <geometry>
        <cylinder length=".1" radius="0.035"/>
      </geometry>
      <material name="black"/>
    </visual>
  </link>

  <joint name="left_front_wheel_joint" type="continuous">
    <axis xyz="0 0 1"/>
    <parent link="left_base"/>
    <child link="left_front_wheel"/>
    <origin rpy="0 1.57075 0" xyz="0 0.133333333333 -0.085"/>
    <limit effort="100" velocity="100"/>
    <dynamics damping="0.0" friction="0.0"/>
  </joint>

  <link name="left_back_wheel">
    <visual>
      <geometry>
        <cylinder length=".1" radius="0.035"/>
      </geometry>
      <material name="black"/>
    </visual>
  </link>

  <joint name="left_back_wheel_joint" type="continuous">
    <axis xyz="0 0 1"/>
    <parent link="left_base"/>
    <child link="left_back_wheel"/>
    <origin rpy="0 1.57075 0" xyz="0 -0.133333333333 -0.085"/>
    <limit effort="100" velocity="100"/>
    <dynamics damping="0.0" friction="0.0"/>
  </joint>

  <link name="head">
    <visual>
      <geometry>
        <cylinder length="0.3" radius="0.14"/>
      </geometry>
      <origin xyz="0 0 -0.15"/>
      <material name="white"/>
    </visual>
  </link>

  <joint name="head_swivel" type="continuous">
    <parent link="base_link"/>
    <child link="head"/>
    <axis xyz="0 0 1"/>
    <origin xyz="0 0 0.3"/>
  </joint>

  <link name="box">
    <visual>
      <geometry>
        <box size=".08 .08 .08"/>
      </geometry>
      <material name="blue"/>
    </visual>
  </link>

  <joint name="tobox" type="fixed">
    <parent link="head"/>
    <child link="box"/>
    <origin xyz="0 0.12 0"/>
  </joint>

</robot>